Workbook

Sheet Read Me
A1: Tunduma Water Supply – Zone Calculator
A2: Hydraulic analysis from the Momba River intake to the Tunduma tanks, split by zone. Every result is a live Excel formula.
A4: WHEN YOU RECEIVE THE REAL LEVELS – 4 STEPS
A5: Step 1 – sheet 'Levels' | B5: type ground, floor, MINIMUM and MAXIMUM water level, inlet level and capacity of every tank / sump / river. Read the 'Check' column: it must say OK.
A6: Step 2 – sheet 'Demands' | B6: type the daily demand of each tank and the WTP losses (if they changed).
A7: Step 3 – zone sheets Z1 … Z7 | B7: only if pipes or pumps changed: DN, length, C, hours, number of pumps, efficiencies, ER duty (blue cells).
A8: Step 4 – sheet 'Summary' | B8: read the pump heads (at minimum and maximum suction level), gravity surplus, tank results and storage. Each zone sheet explains its result in section F.
A9: Optional – Python and PDFs | B9: run 'python levels_from_excel.py results/Tunduma_Zone_Calculator.xlsx' to copy the levels into tunduma_config.json, then 'python run_analysis.py' and the PDF scripts to regenerate every report with the same levels.
A11: COLOUR LEGEND
A12: Blue text, yellow fill | B12: input – edit these
A13: Black text | B13: formula – do not overwrite
A14: Green text | B14: link from another sheet
A15: Green fill, bold | B15: key result
A17: WHY MINIMUM AND MAXIMUM LEVELS MATTER
A18: Pumped zone, design case | B18: suction tank at its MINIMUM level → the pump must lift the most → TDH max (used to size pump and motor).
A19: Pumped zone, low-head case | B19: suction tank at its MAXIMUM level → least lift → TDH min (the pump must also run safely here: it gives more flow unless throttled / VFD).
A20: Gravity zone, design case | B20: supplying tank at its MINIMUM level → least energy available → must still reach every tank (surplus ≥ 0).
A21: Gravity zone, high case | B21: supplying tank at its MAXIMUM level → most energy → the valve must burn the biggest surplus; static pressure (pipe class) uses this level.
A22: Receiving tank | B22: water must arrive at the inlet level (or the maximum level if the inlet is lower / submerged) plus a small residual head.
A24: ZONES (split at every free water surface)
A25: Z1 River-Intake | B25: gravity: Momba River → intake sump (abstraction pipe)
A26: Z2 Intake-Grit | B26: pumped: low-lift pumps, intake sump → grit tank
A27: Z3 Grit-WTP | B27: pumped: high-lift pumps, grit tank → WTP inlet (raw-water main)
A28: Z4 WTP-Ikana | B28: pumped: WTP clear-water pumps → Ikana GBR (treated-water rising main)
A29: Z5 Ikana-Nkangamo | B29: gravity: Ikana GBR → Nkangamo BPS sump
A30: Z6 Nkangamo-Uhuru | B30: pumped: Nkangamo BPS → J-001N (ESR), J-002N (GSR01), J-003N (Ipito) → Uhuru Park GBR
A31: Z7 Uhuru-Chapwa | B31: gravity: Uhuru Park GBR → J-004N → Makambini GSR03 and Chapwa GSR04
A33: METHOD (Bernoulli / energy equation between two water surfaces)
A34: z1 + p1/ρg + V1²/2g + Hp = z2 + p2/ρg + V2²/2g + hL | B34: at tank surfaces p = 0 and V ≈ 0
A35: Pumped zone | B35: Hp = H_req − z1 ; TDH = Hp + station losses
A36: Gravity zone | B36: surplus = z1 − H_req (≥ 0 OK, burnt by an FCV/PRV; < 0 short of head)
A37: H_req (head needed at zone start) | B37: largest of: each destination arrival level + residual + losses on the way, and each critical point crown + min. pressure + losses up to it
A38: Friction (Hazen-Williams) | B38: hf = 10.67 L Q^1.852 / (C^1.852 D^4.8704) ; hL = hf × (1 + minor-loss factor)
A39: Pressure at a point | B39: p = HGL − pipe crown ; working = max(p, static level − crown) ; PN = smallest class ≥ working × 0.0981 bar/m
A40: Surge (Joukowsky) | B40: Δh = a V / g
A42: SOURCE OF THE STARTING VALUES
A43: Employer's Requirements | B43: flows, pipe sizes and lengths, pump duties, tank elevations and capacities.
A44: ASSUMED (to confirm) | B44: operating water levels, inlet levels, WTP inlet, C value, station losses, pipe cover – marked in 'Levels' column M and in cell notes.
A45: Check | B45: column 'Python model' on Summary = run_analysis.py with the starting inputs.

Sheet Levels
A1: Levels of every water surface – ENTER THE REAL LEVELS HERE
A2: Minimum and maximum water levels drive every zone. Blank inlet = the maximum level is used. All levels in m above datum (survey datum).
A4: ID | B4: Facility | C4: Role | D4: Ground level (m) | E4: Floor level (m) | F4: MINIMUM water level (m) | G4: MAXIMUM water level (m) | H4: Inlet level (m) | I4: Capacity (m³) | J4: Water depth (m) | K4: Plan area (m²) | L4: Arrival level used (m) | M4: Source / status | N4: Check
A5: MOMBA_RIVER | B5: Momba (Saisi) River | C5: source: minimum = dry-season low level, maximum = flood level | D5: 1363 | F5: 1361 | G5: 1364.5 | J5: =IF(OR(E5="",G5=""),"",G5-E5) | K5: =IF(OR(I5="",J5="",J5<=0),"",I5/J5) | L5: =IF(H5="",G5,MAX(H5,G5)) -> 1364.5 | M5: levels ASSUMED – confirm | N5: =IF(OR(F5="",G5=""),"ENTER MIN AND MAX",IF(G5<=F5,"MAX must be above MIN",IF(AND(E5<>"",F5<E5),"MIN below floor",IF(AND(H5<>"",H5<G5),"inlet below MAX – MAX used","OK")))) -> OK
A6: MOMBA_INTAKE | B6: Momba Intake - low lift PS | C6: intake sump: minimum = pump start/stop low level (submergence) | D6: 1365.94 | F6: 1360 | G6: 1364 | J6: =IF(OR(E6="",G6=""),"",G6-E6) | K6: =IF(OR(I6="",J6="",J6<=0),"",I6/J6) | L6: =F6 -> 1360 | M6: ER elevation/capacity; levels ASSUMED – confirm | N6: =IF(OR(F6="",G6=""),"ENTER MIN AND MAX",IF(G6<=F6,"MAX must be above MIN",IF(AND(E6<>"",F6<E6),"MIN below floor",IF(AND(H6<>"",H6<G6),"inlet below MAX – MAX used","OK")))) -> OK
A7: GRIT_TANK | B7: Grit tank - high lift PS | C7: grit tank = high-lift pump suction; receives low-lift flow | D7: 1365.94 | F7: 1366.5 | G7: 1368 | H7: 1368 | J7: =IF(OR(E7="",G7=""),"",G7-E7) | K7: =IF(OR(I7="",J7="",J7<=0),"",I7/J7) | L7: =IF(H7="",G7,MAX(H7,G7)) -> 1368 | M7: ER elevation/capacity; levels ASSUMED – confirm | N7: =IF(OR(F7="",G7=""),"ENTER MIN AND MAX",IF(G7<=F7,"MAX must be above MIN",IF(AND(E7<>"",F7<E7),"MIN below floor",IF(AND(H7<>"",H7<G7),"inlet below MAX – MAX used","OK")))) -> OK
A8: MOMBA_WTP | B8: Momba WTP (20,000 m3/day) | C8: inlet = aerator inlet; min/max/capacity = CLEAR-WATER tank (pump suction) | D8: 1372.1 | E8: 1368 | F8: 1368.5 | G8: 1373 | H8: 1378 | I8: 4000 | J8: =IF(OR(E8="",G8=""),"",G8-E8) -> 5 | K8: =IF(OR(I8="",J8="",J8<=0),"",I8/J8) -> 800 | L8: =IF(H8="",G8,H8) -> 1378 | M8: ER elevation/capacity; levels ASSUMED – confirm | N8: =IF(OR(F8="",G8=""),"ENTER MIN AND MAX",IF(G8<=F8,"MAX must be above MIN",IF(AND(E8<>"",F8<E8),"MIN below floor",IF(AND(H8<>"",H8<G8),"inlet below MAX – MAX used","OK")))) -> OK
A9: IKANA_GBR | B9: Ikana (Momba) GBR 3,000 m3 | C9: receives WTP pumping; supplies gravity main | D9: 1663 | E9: 1663 | F9: 1663.3 | G9: 1668 | I9: 3000 | J9: =IF(OR(E9="",G9=""),"",G9-E9) -> 5 | K9: =IF(OR(I9="",J9="",J9<=0),"",I9/J9) -> 600 | L9: =IF(H9="",G9,MAX(H9,G9)) -> 1668 | M9: ER elevation/capacity; levels ASSUMED – confirm | N9: =IF(OR(F9="",G9=""),"ENTER MIN AND MAX",IF(G9<=F9,"MAX must be above MIN",IF(AND(E9<>"",F9<E9),"MIN below floor",IF(AND(H9<>"",H9<G9),"inlet below MAX – MAX used","OK")))) -> OK
A10: NKANGAMO_BPS | B10: Nkangamo BPS | C10: BPS sump: receives gravity main; BPS pump suction | D10: 1555.5 | E10: 1552.5 | F10: 1553 | G10: 1557 | H10: 1557.5 | I10: 2000 | J10: =IF(OR(E10="",G10=""),"",G10-E10) -> 4.5 | K10: =IF(OR(I10="",J10="",J10<=0),"",I10/J10) -> 444.44444 | L10: =IF(H10="",G10,MAX(H10,G10)) -> 1557.5 | M10: ER elevation/capacity; levels ASSUMED – confirm | N10: =IF(OR(F10="",G10=""),"ENTER MIN AND MAX",IF(G10<=F10,"MAX must be above MIN",IF(AND(E10<>"",F10<E10),"MIN below floor",IF(AND(H10<>"",H10<G10),"inlet below MAX – MAX used","OK")))) -> OK
A11: UHURU_PARK_GBR | B11: Uhuru Park GBR 5,000 m3 (Tunduma) | C11: receives BPS main; supplies town + J-004N | D11: 1697.3 | E11: 1697.3 | F11: 1697.6 | G11: 1702.3 | I11: 5000 | J11: =IF(OR(E11="",G11=""),"",G11-E11) -> 5 | K11: =IF(OR(I11="",J11="",J11<=0),"",I11/J11) -> 1000 | L11: =IF(H11="",G11,MAX(H11,G11)) -> 1702.3 | M11: ER elevation/capacity; levels ASSUMED – confirm | N11: =IF(OR(F11="",G11=""),"ENTER MIN AND MAX",IF(G11<=F11,"MAX must be above MIN",IF(AND(E11<>"",F11<E11),"MIN below floor",IF(AND(H11<>"",H11<G11),"inlet below MAX – MAX used","OK")))) -> OK
A12: TUNDUMA_ESR | B12: Existing Tunduma ESR 120 m3 | C12: existing elevated tank (from J-001N) | D12: 1700 | E12: 1703.5 | F12: 1703.5 | G12: 1706.5 | I12: 120 | J12: =IF(OR(E12="",G12=""),"",G12-E12) -> 3 | K12: =IF(OR(I12="",J12="",J12<=0),"",I12/J12) -> 40 | L12: =IF(H12="",G12,MAX(H12,G12)) -> 1706.5 | M12: ER elevation/capacity; levels ASSUMED – confirm | N12: =IF(OR(F12="",G12=""),"ENTER MIN AND MAX",IF(G12<=F12,"MAX must be above MIN",IF(AND(E12<>"",F12<E12),"MIN below floor",IF(AND(H12<>"",H12<G12),"inlet below MAX – MAX used","OK")))) -> OK
A13: UHURU_GSR01 | B13: Existing Tunduma Uhuru GSR 01 500 m3 | C13: existing tank (from J-002N) | D13: 1698.4 | E13: 1698.4 | F13: 1698.4 | G13: 1701.4 | I13: 500 | J13: =IF(OR(E13="",G13=""),"",G13-E13) -> 3 | K13: =IF(OR(I13="",J13="",J13<=0),"",I13/J13) -> 166.66667 | L13: =IF(H13="",G13,MAX(H13,G13)) -> 1701.4 | M13: ER elevation/capacity; levels ASSUMED – confirm | N13: =IF(OR(F13="",G13=""),"ENTER MIN AND MAX",IF(G13<=F13,"MAX must be above MIN",IF(AND(E13<>"",F13<E13),"MIN below floor",IF(AND(H13<>"",H13<G13),"inlet below MAX – MAX used","OK")))) -> OK
A14: IPITO_GSR02 | B14: Existing Tunduma Ipito GSR 02 | C14: existing tank (from J-003N) | D14: 1681.2 | E14: 1681.2 | F14: 1681.2 | G14: 1684.2 | I14: 200 | J14: =IF(OR(E14="",G14=""),"",G14-E14) -> 3 | K14: =IF(OR(I14="",J14="",J14<=0),"",I14/J14) -> 66.666667 | L14: =IF(H14="",G14,MAX(H14,G14)) -> 1684.2 | M14: ER elevation/capacity; levels ASSUMED – confirm | N14: =IF(OR(F14="",G14=""),"ENTER MIN AND MAX",IF(G14<=F14,"MAX must be above MIN",IF(AND(E14<>"",F14<E14),"MIN below floor",IF(AND(H14<>"",H14<G14),"inlet below MAX – MAX used","OK")))) -> OK
A15: MAKAMBINI_GSR03 | B15: Existing Tunduma Makambini GSR 03 | C15: existing tank (from J-004N, gravity) | D15: 1655.7 | E15: 1655.7 | F15: 1655.7 | G15: 1658.7 | I15: 200 | J15: =IF(OR(E15="",G15=""),"",G15-E15) -> 3 | K15: =IF(OR(I15="",J15="",J15<=0),"",I15/J15) -> 66.666667 | L15: =IF(H15="",G15,MAX(H15,G15)) -> 1658.7 | M15: ER | N15: =IF(OR(F15="",G15=""),"ENTER MIN AND MAX",IF(G15<=F15,"MAX must be above MIN",IF(AND(E15<>"",F15<E15),"MIN below floor",IF(AND(H15<>"",H15<G15),"inlet below MAX – MAX used","OK")))) -> OK
A16: CHAPWA_GSR04 | B16: Existing Tunduma Chapwa GSR 04 | C16: existing tank (from J-004N, gravity) | D16: 1521.4 | E16: 1521.4 | F16: 1521.4 | G16: 1524.4 | I16: 200 | J16: =IF(OR(E16="",G16=""),"",G16-E16) -> 3 | K16: =IF(OR(I16="",J16="",J16<=0),"",I16/J16) -> 66.666667 | L16: =IF(H16="",G16,MAX(H16,G16)) -> 1524.4 | M16: ER | N16: =IF(OR(F16="",G16=""),"ENTER MIN AND MAX",IF(G16<=F16,"MAX must be above MIN",IF(AND(E16<>"",F16<E16),"MIN below floor",IF(AND(H16<>"",H16<G16),"inlet below MAX – MAX used","OK")))) -> OK
A18: Notes
A19: MINIMUM level = lowest operating level (pump cut-out / bottom water level, BWL). MAXIMUM level = top water level (TWL, overflow level).
A20: Floor and capacity are used for the depth/area check and the Storage sheet; they do not change the hydraulics.
A21: If the real inlet is a free fall above the tank, enter its level in 'Inlet level'; if it enters from below, leave it blank.
A22: After typing new levels, look at Summary – every zone, tank and pressure check updates.

Sheet Summary
A1: Summary of all zones
A2: Linked to the zone sheets (green). Change levels on 'Levels' and read the result here. 'Python model' = run_analysis.py with the starting inputs.
A4: Zones
A5: Zone | B5: Type | C5: Flow (l/s) | D5: Velocity first pipe (m/s) | E5: hL first pipe (m) | F5: H_req (m a.s.l.) | G5: Set by | H5: Design: TDH (m) / surplus (m) | I5: Start at MAX level: TDH (m) / surplus (m) | J5: ER duty head (m) | K5: TDH − ER (m) | L5: Shaft kW per pump | M5: Motor kW per pump | N5: Energy (kWh/d) | O5: Lowest pressure on route (m) | P5: Python model (m) | Q5: Excel − Python (m)
A6: Z1 River-Intake | B6: gravity | C6: ='Z1 River-Intake'!K12 -> 271.53253 | D6: ='Z1 River-Intake'!M12 -> 0.96034987 | E6: ='Z1 River-Intake'!P12 -> 0.17817373 | F6: ='Z1 River-Intake'!$B$25 -> 1360.1782 | G6: ='Z1 River-Intake'!$B$26 -> MOMBA_INTAKE | H6: ='Z1 River-Intake'!$B$27 -> 0.82182627 | I6: ='Z1 River-Intake'!$B$28 -> 4.3218263 | J6: – | K6: – | L6: – | M6: – | N6: – | O6: ='Z1 River-Intake'!$B$30 -> no points between tanks | P6: 0.82 | Q6: =H6-P6 -> 0.0018262659
A7: Z2 Intake-Grit | B7: pumped | C7: ='Z2 Intake-Grit'!K18 -> 271.53253 | D7: ='Z2 Intake-Grit'!M18 -> 0.96034987 | E7: ='Z2 Intake-Grit'!P18 -> 0.05345212 | F7: ='Z2 Intake-Grit'!$B$31 -> 1369.0535 | G7: ='Z2 Intake-Grit'!$B$32 -> GRIT_TANK | H7: ='Z2 Intake-Grit'!$B$34 -> 12.053452 | I7: ='Z2 Intake-Grit'!$B$35 -> 8.0534521 | J7: ='Z2 Intake-Grit'!$B$14 -> 10 | K7: ='Z2 Intake-Grit'!$B$46 -> 2.0534521 | L7: ='Z2 Intake-Grit'!$B$40 -> 42.809589 | M7: ='Z2 Intake-Grit'!$B$42 -> 55 | N7: ='Z2 Intake-Grit'!$B$43 -> 1001.9265 | O7: ='Z2 Intake-Grit'!$B$47 -> no points between tanks | P7: 12.05 | Q7: =H7-P7 -> 0.0034521202
A8: Z3 Grit-WTP | B8: pumped | C8: ='Z3 Grit-WTP'!K18 -> 271.53253 | D8: ='Z3 Grit-WTP'!M18 -> 0.96034987 | E8: ='Z3 Grit-WTP'!P18 -> 1.9216037 | F8: ='Z3 Grit-WTP'!$B$33 -> 1380.9216 | G8: ='Z3 Grit-WTP'!$B$34 -> MOMBA_WTP | H8: ='Z3 Grit-WTP'!$B$36 -> 17.421604 | I8: ='Z3 Grit-WTP'!$B$37 -> 15.921604 | J8: ='Z3 Grit-WTP'!$B$14 -> 25 | K8: ='Z3 Grit-WTP'!$B$48 -> -7.5783963 | L8: ='Z3 Grit-WTP'!$B$42 -> 61.87536 | M8: ='Z3 Grit-WTP'!$B$44 -> 75 | N8: ='Z3 Grit-WTP'!$B$45 -> 1448.1467 | O8: ='Z3 Grit-WTP'!$B$49 -> 8.3046103 | P8: 17.42 | Q8: =H8-P8 -> 0.0016037227
A9: Z4 WTP-Ikana | B9: pumped | C9: ='Z4 WTP-Ikana'!K18 -> 252.52525 | D9: ='Z4 WTP-Ikana'!M18 -> 0.89312538 | E9: ='Z4 WTP-Ikana'!P18 -> 30.63242 | F9: ='Z4 WTP-Ikana'!$B$33 -> 1699.6324 | G9: ='Z4 WTP-Ikana'!$B$34 -> IKANA_GBR | H9: ='Z4 WTP-Ikana'!$B$36 -> 334.13242 | I9: ='Z4 WTP-Ikana'!$B$37 -> 329.63242 | J9: ='Z4 WTP-Ikana'!$B$14 -> 330 | K9: ='Z4 WTP-Ikana'!$B$48 -> 4.1324197 | L9: ='Z4 WTP-Ikana'!$B$42 -> 353.73382 | M9: ='Z4 WTP-Ikana'!$B$44 -> 450 | N9: ='Z4 WTP-Ikana'!$B$45 -> 24575.191 | O9: ='Z4 WTP-Ikana'!$B$49 -> 8.8711377 | P9: 334.13 | Q9: =H9-P9 -> 0.0024197216
A10: Z5 Ikana-Nkangamo | B10: gravity | C10: ='Z5 Ikana-Nkangamo'!K12 -> 231.48148 | D10: ='Z5 Ikana-Nkangamo'!M12 -> 0.81869827 | E10: ='Z5 Ikana-Nkangamo'!P12 -> 51.615046 | F10: ='Z5 Ikana-Nkangamo'!$B$27 -> 1610.115 | G10: ='Z5 Ikana-Nkangamo'!$B$28 -> NKANGAMO_BPS | H10: ='Z5 Ikana-Nkangamo'!$B$29 -> 53.184954 | I10: ='Z5 Ikana-Nkangamo'!$B$30 -> 57.884954 | J10: – | K10: – | L10: – | M10: – | N10: – | O10: ='Z5 Ikana-Nkangamo'!$B$32 -> 65.611726 | P10: 53.18 | Q10: =H10-P10 -> 0.0049535157
A11: Z6 Nkangamo-Uhuru | B11: pumped | C11: ='Z6 Nkangamo-Uhuru'!K18 -> 252.52525 | D11: ='Z6 Nkangamo-Uhuru'!M18 -> 0.89312538 | E11: ='Z6 Nkangamo-Uhuru'!P18 -> 30.501264 | F11: ='Z6 Nkangamo-Uhuru'!$B$50 -> 1738.2284 | G11: ='Z6 Nkangamo-Uhuru'!$B$51 -> TUNDUMA_ESR | H11: ='Z6 Nkangamo-Uhuru'!$B$53 -> 188.22839 | I11: ='Z6 Nkangamo-Uhuru'!$B$54 -> 184.22839 | J11: ='Z6 Nkangamo-Uhuru'!$B$14 -> 221 | K11: ='Z6 Nkangamo-Uhuru'!$B$65 -> -32.771611 | L11: ='Z6 Nkangamo-Uhuru'!$B$59 -> 298.9058 | M11: ='Z6 Nkangamo-Uhuru'!$B$61 -> 355 | N11: ='Z6 Nkangamo-Uhuru'!$B$62 -> 13844.058 | O11: ='Z6 Nkangamo-Uhuru'!$B$66 -> 6.6727404 | P11: 188.23 | Q11: =H11-P11 -> -0.001610638
A12: Z7 Uhuru-Chapwa | B12: gravity | C12: ='Z7 Uhuru-Chapwa'!K12 -> 14.400463 | D12: ='Z7 Uhuru-Chapwa'!M12 -> 0.81489951 | E12: ='Z7 Uhuru-Chapwa'!P12 -> 10.353559 | F12: ='Z7 Uhuru-Chapwa'!$B$37 -> 1701.5073 | G12: ='Z7 Uhuru-Chapwa'!$B$38 -> point on UHURU_J004N | H12: ='Z7 Uhuru-Chapwa'!$B$39 -> -3.9073317 | I12: ='Z7 Uhuru-Chapwa'!$B$40 -> 0.79266833 | J12: – | K12: – | L12: – | M12: – | N12: – | O12: ='Z7 Uhuru-Chapwa'!$B$42 -> -1.9075966 | P12: -3.91 | Q12: =H12-P12 -> 0.0026683296
A13: Total pumping energy | N13: =SUM(N6:N12) -> 40869.323
A14: Pumped zones: H = pump head with suction at MINIMUM level (design), I = with suction at MAXIMUM level. Gravity zones: H/I = spare head with the supplying tank at MIN/MAX level (≥ 0 OK, burnt by a valve; < 0 short of head).
A16: Tanks and sumps
A17: Tank | B17: MIN level (m) | C17: MAX level (m) | D17: Arrival level (m) | E17: Fed by zone | F17: Arriving HGL (m) | G17: Excess head, design (m) | H17: Excess head, max (m) | I17: Inlet comment | J17: Capacity (m³) | K17: Storage required (m³) | L17: Storage status
A18: MOMBA_INTAKE | B18: =Levels!$F$6 -> 1360 | C18: =Levels!$G$6 -> 1364 | D18: =Levels!$L$6 -> 1360 | E18: Z1 River-Intake | F18: ='Z1 River-Intake'!I16 -> 1360.8218 | G18: ='Z1 River-Intake'!J16 -> 0.82182627 | H18: ='Z1 River-Intake'!K16 -> 4.3218263 | I18: ='Z1 River-Intake'!L16 -> OK | J18: =IF(Levels!$I$6="","",Levels!$I$6) | K18: – | L18: –
A19: GRIT_TANK | B19: =Levels!$F$7 -> 1366.5 | C19: =Levels!$G$7 -> 1368 | D19: =Levels!$L$7 -> 1368 | E19: Z2 Intake-Grit | F19: ='Z2 Intake-Grit'!I22 -> 1369 | G19: ='Z2 Intake-Grit'!J22 -> 0 | H19: ='Z2 Intake-Grit'!K22 -> 4 | I19: ='Z2 Intake-Grit'!L22 -> OK | J19: =IF(Levels!$I$7="","",Levels!$I$7) | K19: – | L19: –
A20: MOMBA_WTP | B20: =Levels!$F$8 -> 1368.5 | C20: =Levels!$G$8 -> 1373 | D20: =Levels!$L$8 -> 1378 | E20: Z3 Grit-WTP | F20: ='Z3 Grit-WTP'!I22 -> 1379 | G20: ='Z3 Grit-WTP'!J22 -> 0 | H20: ='Z3 Grit-WTP'!K22 -> 1.5 | I20: ='Z3 Grit-WTP'!L22 -> OK | J20: =IF(Levels!$I$8="","",Levels!$I$8) -> 4000 | K20: – | L20: –
A21: IKANA_GBR | B21: =Levels!$F$9 -> 1663.3 | C21: =Levels!$G$9 -> 1668 | D21: =Levels!$L$9 -> 1668 | E21: Z4 WTP-Ikana | F21: ='Z4 WTP-Ikana'!I22 -> 1669 | G21: ='Z4 WTP-Ikana'!J22 -> 0 | H21: ='Z4 WTP-Ikana'!K22 -> 4.5 | I21: ='Z4 WTP-Ikana'!L22 -> OK | J21: =IF(Levels!$I$9="","",Levels!$I$9) -> 3000 | K21: =Storage!I5 -> 1666.6667 | L21: =Storage!L5 -> OK
A22: NKANGAMO_BPS | B22: =Levels!$F$10 -> 1553 | C22: =Levels!$G$10 -> 1557 | D22: =Levels!$L$10 -> 1557.5 | E22: Z5 Ikana-Nkangamo | F22: ='Z5 Ikana-Nkangamo'!I16 -> 1611.685 | G22: ='Z5 Ikana-Nkangamo'!J16 -> 53.184954 | H22: ='Z5 Ikana-Nkangamo'!K16 -> 57.884954 | I22: ='Z5 Ikana-Nkangamo'!L16 -> fit flow control valve / PRV (burns 53.2–57.9 m) | J22: =IF(Levels!$I$10="","",Levels!$I$10) -> 2000 | K22: =Storage!I6 -> 1666.6667 | L22: =Storage!L6 -> OK
A23: TUNDUMA_ESR | B23: =Levels!$F$12 -> 1703.5 | C23: =Levels!$G$12 -> 1706.5 | D23: =Levels!$L$12 -> 1706.5 | E23: Z6 Nkangamo-Uhuru | F23: ='Z6 Nkangamo-Uhuru'!I28 -> 1707.5 | G23: ='Z6 Nkangamo-Uhuru'!J28 -> 0 | H23: ='Z6 Nkangamo-Uhuru'!K28 -> 4 | I23: ='Z6 Nkangamo-Uhuru'!L28 -> OK | J23: =IF(Levels!$I$12="","",Levels!$I$12) -> 120 | K23: =Storage!I8 -> 30.96 | L23: =Storage!L8 -> OK
A24: UHURU_GSR01 | B24: =Levels!$F$13 -> 1698.4 | C24: =Levels!$G$13 -> 1701.4 | D24: =Levels!$L$13 -> 1701.4 | E24: Z6 Nkangamo-Uhuru | F24: ='Z6 Nkangamo-Uhuru'!I29 -> 1707.2014 | G24: ='Z6 Nkangamo-Uhuru'!J29 -> 4.8013516 | H24: ='Z6 Nkangamo-Uhuru'!K29 -> 8.8013516 | I24: ='Z6 Nkangamo-Uhuru'!L29 -> fit flow control valve / PRV (burns 4.8–8.8 m) | J24: =IF(Levels!$I$13="","",Levels!$I$13) -> 500 | K24: =Storage!I9 -> 128.88 | L24: =Storage!L9 -> OK
A25: IPITO_GSR02 | B25: =Levels!$F$14 -> 1681.2 | C25: =Levels!$G$14 -> 1684.2 | D25: =Levels!$L$14 -> 1684.2 | E25: Z6 Nkangamo-Uhuru | F25: ='Z6 Nkangamo-Uhuru'!I30 -> 1698.4412 | G25: ='Z6 Nkangamo-Uhuru'!J30 -> 13.241179 | H25: ='Z6 Nkangamo-Uhuru'!K30 -> 17.241179 | I25: ='Z6 Nkangamo-Uhuru'!L30 -> fit flow control valve / PRV (burns 13.2–17.2 m) | J25: =IF(Levels!$I$14="","",Levels!$I$14) -> 200 | K25: =Storage!I10 -> 51.841667 | L25: =Storage!L10 -> OK
A26: UHURU_PARK_GBR | B26: =Levels!$F$11 -> 1697.6 | C26: =Levels!$G$11 -> 1702.3 | D26: =Levels!$L$11 -> 1702.3 | E26: Z6 Nkangamo-Uhuru | F26: ='Z6 Nkangamo-Uhuru'!I31 -> 1707.4769 | G26: ='Z6 Nkangamo-Uhuru'!J31 -> 4.1768894 | H26: ='Z6 Nkangamo-Uhuru'!K31 -> 8.1768894 | I26: ='Z6 Nkangamo-Uhuru'!L31 -> fit flow control valve / PRV (burns 4.2–8.2 m) | J26: =IF(Levels!$I$11="","",Levels!$I$11) -> 5000 | K26: =Storage!I7 -> 1454.985 | L26: =Storage!L7 -> OK
A27: MAKAMBINI_GSR03 | B27: =Levels!$F$15 -> 1655.7 | C27: =Levels!$G$15 -> 1658.7 | D27: =Levels!$L$15 -> 1658.7 | E27: Z7 Uhuru-Chapwa | F27: ='Z7 Uhuru-Chapwa'!I18 -> 1680.7175 | G27: ='Z7 Uhuru-Chapwa'!J18 -> 21.017451 | H27: ='Z7 Uhuru-Chapwa'!K18 -> 25.717451 | I27: ='Z7 Uhuru-Chapwa'!L18 -> fit flow control valve / PRV (burns 21.0–25.7 m) | J27: =IF(Levels!$I$15="","",Levels!$I$15) -> 200 | K27: =Storage!I11 -> 0 | L27: =Storage!L11 -> OK
A28: CHAPWA_GSR04 | B28: =Levels!$F$16 -> 1521.4 | C28: =Levels!$G$16 -> 1524.4 | D28: =Levels!$L$16 -> 1524.4 | E28: Z7 Uhuru-Chapwa | F28: ='Z7 Uhuru-Chapwa'!I19 -> 1650.3656 | G28: ='Z7 Uhuru-Chapwa'!J19 -> 124.96558 | H28: ='Z7 Uhuru-Chapwa'!K19 -> 129.66558 | I28: ='Z7 Uhuru-Chapwa'!L19 -> fit flow control valve / PRV (burns 125.0–129.7 m) | J28: =IF(Levels!$I$16="","",Levels!$I$16) -> 200 | K28: =Storage!I12 -> 0 | L28: =Storage!L12 -> OK
A30: Levels check (from sheet Levels)
A31: =IF(COUNTIF(Levels!$N$5:$N$16,"OK")=12,"All levels entered and consistent","CHECK sheet Levels – "&(12-COUNTIF(Levels!$N$5:$N$16,"OK"))&" row(s) need attention") -> All levels entered and consistent

Sheet Demands
A1: Demands and design flows
A2: Daily volumes (m³/d) supplied by each tank; pipe volumes follow by mass balance.
A4: Tank demands (ER schematic, design year 2035)
A5: Uhuru Park GBR – town supply | B5: 16215.62 | C5: m³/d | D5: ER schematic
A6: Existing Uhuru GSR 01 | B6: 1546.56 | C6: m³/d | D6: ER schematic
A7: Existing Tunduma ESR | B7: 371.52 | C7: m³/d | D7: ER schematic
A8: Existing Ipito GSR 02 | B8: 622.1 | C8: m³/d | D8: ER schematic
A9: Existing Makambini GSR 03 | B9: 622.1 | C9: m³/d | D9: ER schematic
A10: Existing Chapwa GSR 04 | B10: 622.1 | C10: m³/d | D10: ER schematic
A11: WTP + intake-to-WTP losses | B11: 0.07 | C11: – | D11: ER Table 8: 2 % + 5 %
A13: Daily volume in each pipe (mass balance, downstream → upstream)
A14: J-004N → Makambini | B14: =$B$9 -> 622.1 | C14: m³/d
A15: J-004N → Chapwa | B15: =$B$10 -> 622.1 | C15: m³/d
A16: Uhuru Park → J-004N | B16: =$B$14+$B$15 -> 1244.2 | C16: m³/d
A17: J-003N → Uhuru Park GBR | B17: =$B$5+$B$16 -> 17459.82 | C17: m³/d
A18: J-003N → Ipito | B18: =$B$8 -> 622.1 | C18: m³/d
A19: J-002N → GSR01 | B19: =$B$6 -> 1546.56 | C19: m³/d
A20: J-001N → ESR | B20: =$B$7 -> 371.52 | C20: m³/d
A21: J-002N → J-003N | B21: =$B$17+$B$18 -> 18081.92 | C21: m³/d
A22: J-001N → J-002N | B22: =$B$21+$B$19 -> 19628.48 | C22: m³/d
A23: Nkangamo BPS → J-001N | B23: =$B$22+$B$20 -> 20000 | C23: m³/d
A24: Ikana GBR → Nkangamo BPS | B24: =$B$23 -> 20000 | C24: m³/d
A25: WTP → Ikana GBR (net WTP output) | B25: =$B$24 -> 20000 | C25: m³/d
A26: Raw water: intake → WTP | B26: =$B$25/(1-$B$11) -> 21505.376 | C26: m³/d | D26: net ÷ (1 − losses)
A27: Low-lift → grit tank | B27: =$B$26 -> 21505.376 | C27: m³/d
A28: River → intake sump | B28: =$B$26 -> 21505.376 | C28: m³/d

Sheet Global
A1: Global constants and design criteria
A2: Used by every zone (named cells).
A4: Constants and criteria
A5: Gravitational acceleration g | B5: 9.81 | C5: m/s² | D5: physical constant
A6: Minor losses as fraction of friction | B6: 0.1 | C6: – | D6: ASSUMED 10 % (bends, valves, fittings)
A7: Losses inside each pump station | B7: 3 | C7: m | D7: ASSUMED pipework/valves/meter
A8: Residual head above a tank inlet | B8: 1 | C8: m | D8: ASSUMED safety margin
A9: Pipe crown depth below ground | B9: 1.2 | C9: m | D9: ASSUMED
A10: Minimum pressure at pipe crown along mains | B10: 2 | C10: m | D10: ASSUMED
A11: Minimum pressure at junctions / delivery | B11: 5 | C11: m | D11: ER Table 7
A12: Pressure wave speed a (steel) | B12: 1000 | C12: m/s | D12: ASSUMED, for surge
A13: Motor size margin over shaft power | B13: 1.15 | C13: – | D13: common practice
A14: Electricity tariff | B14: 0 | C14: per kWh | D14: enter the TANESCO tariff
A15: Bar per metre of water | B15: 0.0981 | C15: bar/m | D15: ρg/10⁵
A16: Default Hazen-Williams C | B16: 120 | C16: – | D16: ASSUMED, cement-lined steel (aged)
A17: Excess head above which a flow control valve is flagged | B17: 5 | C17: m | D17: judgement
A19: Pipe pressure classes (PN, bar)
A20: PN10 | B20: 10
A21: PN16 | B21: 16
A22: PN25 | B22: 25
A23: PN30 | B23: 30
A24: PN40 | B24: 40
A25: PN64 | B25: 64
A27: Standard motor sizes (kW)
B28: 0.75
B29: 1.1
B30: 1.5
B31: 2.2
B32: 3
B33: 4
B34: 5.5
B35: 7.5
B36: 11
B37: 15
B38: 18.5
B39: 22
... B77: 6300

Sheet Z1 River-Intake
A1: Zone 1 – Momba River to intake sump (gravity)
A2: The river fills the intake sump by gravity through the abstraction pipe. The river at its MINIMUM (dry-season) level must stay above the sump MINIMUM level plus the pipe loss, otherwise the low-lift pumps lose submergence.
A4: A. Inputs (levels come from sheet 'Levels')
A5: Start: MOMBA_RIVER MINIMUM water level | B5: =Levels!$F$5 -> 1361 | C5: m a.s.l. | D5: point 1 of Bernoulli, design case (least energy at the start)
A6: Start: MOMBA_RIVER MAXIMUM water level | B6: =Levels!$G$5 -> 1364.5 | C6: m a.s.l. | D6: low-head case for pumps / highest energy for gravity
A7: Operating hours per day | B7: 22 | C7: h/d | D7: carries the intake pump flow while the pumps run
A8: Static level for pressure class | B8: =$B$6 -> 1364.5 | C8: m a.s.l. | D8: MAXIMUM level of the supplying tank (water at rest)
A10: B. Pipes – flow (continuity) and friction (Hazen-Williams)
A11: Pipe | B11: From | C11: To | D11: Upstream pipe | E11: DN | F11: Internal D (mm) | G11: Length L (m) | H11: C (H-W) | I11: Daily volume (m³/d) | J11: Q (m³/s) | K11: Q (l/s) | L11: Area (m²) | M11: V (m/s) | N11: hf friction (m) | O11: hm minor (m) | P11: hL total (m) | Q11: Gradient (m/km) | R11: Loss before this pipe (m) | S11: HGL start (m) | T11: HGL end (m) | U11: Surge Δh = aV/g (m)
A12: ABSTRACTION | B12: MOMBA_RIVER | C12: MOMBA_INTAKE | D12: – | E12: 600 | F12: =E12 -> 600 | G12: 100 | H12: =C_default -> 120 | I12: =Demands!$B$28 -> 21505.376 | J12: =I12/($B$7*3600) -> 0.27153253 | K12: =J12*1000 -> 271.53253 | L12: =PI()*(F12/1000)^2/4 -> 0.28274334 | M12: =J12/L12 -> 0.96034987 | N12: =10.67*G12*J12^1.852/(H12^1.852*(F12/1000)^4.8704) -> 0.16197612 | O12: =k_minor*N12 -> 0.016197612 | P12: =N12+O12 -> 0.17817373 | Q12: =P12/G12*1000 -> 1.7817373 | R12: 0 | S12: =$B$5-R12 -> 1361 | T12: =S12-P12 -> 1360.8218 | U12: =wave*M12/g -> 97.894992
A14: C. Destinations – Bernoulli to each receiving water surface (levels from 'Levels')
A15: Destination | B15: Ends with pipe | C15: MIN level (m) | D15: MAX level (m) | E15: Arrival level (m) | F15: Residual (m) | G15: z2 = arrival + residual (m) | H15: Head needed at zone start = z2 + losses (m) | I15: Arriving HGL, design case (m) | J15: Excess head, design case (m) | K15: Excess head, start at MAX level (m) | L15: Comment
A16: MOMBA_INTAKE | B16: ABSTRACTION | C16: =Levels!$F$6 -> 1360 | D16: =Levels!$G$6 -> 1364 | E16: =Levels!$L$6 -> 1360 | F16: 0 | G16: =E16+F16 -> 1360 | H16: =G16+R12+P12 -> 1360.1782 | I16: =T12 -> 1360.8218 | J16: =I16-G16 -> 0.82182627 | K16: =J16+($B$6-$B$5) -> 4.3218263 | L16: =IF(J16<-0.005,"NOT REACHED – more head needed",IF(K16>fcv_limit,"fit flow control valve / PRV (burns "&TEXT(J16,"0.0")&"–"&TEXT(K16,"0.0")&" m)","OK")) -> OK
A18: D. Critical points along the pipes – pressure check (add your own rows)
A19: Pipe | B19: Chainage in pipe x (m) | C19: Ground level (m) | D19: Pipe crown (m) | E19: Head needed at zone start (m) | F19: HGL at point (m) | G19: Pressure (m) | H19: Static (m) | I19: Working (m) | J19: Working (bar) | K19: PN required | L19: Transient min = p − Δh (m) | M19: Note | N19: Status
D20: =IF($A20="","",C20-cover) | E20: =IF($A20="","",D20+p_min+INDEX($R$12:$R$12,MATCH($A20,$A$12:$A$12,0))+INDEX($P$12:$P$12,MATCH($A20,$A$12:$A$12,0))*B20/INDEX($G$12:$G$12,MATCH($A20,$A$12:$A$12,0))) | F20: =IF($A20="","",INDEX($S$12:$S$12,MATCH($A20,$A$12:$A$12,0))-INDEX($P$12:$P$12,MATCH($A20,$A$12:$A$12,0))*B20/INDEX($G$12:$G$12,MATCH($A20,$A$12:$A$12,0))) | G20: =IF($A20="","",F20-D20) | H20: =IF($A20="","",$B$8-D20) | I20: =IF($A20="","",MAX(G20,H20)) | J20: =IF($A20="","",I20*bar_per_m) | K20: =IF($A20="","",IFERROR("PN"&SMALL(PN_list,COUNTIF(PN_list,"<"&J20)+1),"> max PN")) | L20: =IF($A20="","",G20-INDEX($U$12:$U$12,MATCH($A20,$A$12:$A$12,0))) | M20: add a point: pipe ID, chainage, ground level | N20: =IF($A20="","",IF(G20<0,"NEGATIVE PRESSURE",IF(G20<p_min-0.005,"below minimum","OK")))
D21: =IF($A21="","",C21-cover) | E21: =IF($A21="","",D21+p_min+INDEX($R$12:$R$12,MATCH($A21,$A$12:$A$12,0))+INDEX($P$12:$P$12,MATCH($A21,$A$12:$A$12,0))*B21/INDEX($G$12:$G$12,MATCH($A21,$A$12:$A$12,0))) | F21: =IF($A21="","",INDEX($S$12:$S$12,MATCH($A21,$A$12:$A$12,0))-INDEX($P$12:$P$12,MATCH($A21,$A$12:$A$12,0))*B21/INDEX($G$12:$G$12,MATCH($A21,$A$12:$A$12,0))) | G21: =IF($A21="","",F21-D21) | H21: =IF($A21="","",$B$8-D21) | I21: =IF($A21="","",MAX(G21,H21)) | J21: =IF($A21="","",I21*bar_per_m) | K21: =IF($A21="","",IFERROR("PN"&SMALL(PN_list,COUNTIF(PN_list,"<"&J21)+1),"> max PN")) | L21: =IF($A21="","",G21-INDEX($U$12:$U$12,MATCH($A21,$A$12:$A$12,0))) | M21: add a point: pipe ID, chainage, ground level | N21: =IF($A21="","",IF(G21<0,"NEGATIVE PRESSURE",IF(G21<p_min-0.005,"below minimum","OK")))
D22: =IF($A22="","",C22-cover) | E22: =IF($A22="","",D22+p_min+INDEX($R$12:$R$12,MATCH($A22,$A$12:$A$12,0))+INDEX($P$12:$P$12,MATCH($A22,$A$12:$A$12,0))*B22/INDEX($G$12:$G$12,MATCH($A22,$A$12:$A$12,0))) | F22: =IF($A22="","",INDEX($S$12:$S$12,MATCH($A22,$A$12:$A$12,0))-INDEX($P$12:$P$12,MATCH($A22,$A$12:$A$12,0))*B22/INDEX($G$12:$G$12,MATCH($A22,$A$12:$A$12,0))) | G22: =IF($A22="","",F22-D22) | H22: =IF($A22="","",$B$8-D22) | I22: =IF($A22="","",MAX(G22,H22)) | J22: =IF($A22="","",I22*bar_per_m) | K22: =IF($A22="","",IFERROR("PN"&SMALL(PN_list,COUNTIF(PN_list,"<"&J22)+1),"> max PN")) | L22: =IF($A22="","",G22-INDEX($U$12:$U$12,MATCH($A22,$A$12:$A$12,0))) | M22: add a point: pipe ID, chainage, ground level | N22: =IF($A22="","",IF(G22<0,"NEGATIVE PRESSURE",IF(G22<p_min-0.005,"below minimum","OK")))
A24: E. Bernoulli result
A25: Head needed at zone start H_req | B25: =MAX($H$16:$H$16,$E$20:$E$22) -> 1360.1782 | C25: m a.s.l. | D25: largest of sections C, C2 (junctions) and D (points)
A26: Set by | B26: =IF(MAX($E$20:$E$22)>=MAX($H$16:$H$16),"point on "&INDEX($A$20:$A$22,MATCH(MAX($E$20:$E$22),$E$20:$E$22,0)),INDEX($A$16:$A$16,MATCH(MAX($H$16:$H$16),$H$16:$H$16,0))) -> MOMBA_INTAKE | D26: governing destination, junction or point
A27: Surplus = z1 − H_req (start at MINIMUM level) | B27: =$B$5-$B$25 -> 0.82182627 | C27: m | D27: design case: must be ≥ 0
A28: Surplus with start at MAXIMUM level | B28: =$B$6-$B$25 -> 4.3218263 | C28: m | D28: largest head the valve must burn
A29: Status | B29: =IF($B$27<-0.005,"SHORT OF HEAD at minimum level – bigger pipe, lower outlet, higher tank or pump","OK – valve burns "&TEXT($B$27,"0.0")&" to "&TEXT($B$28,"0.0")&" m") -> OK – valve burns 0.8 to 4.3 m
A30: Lowest pressure at any survey point (sheet Profile) | B30: =IF(COUNTIFS(Profile!$A$5:$A$2360,"Z1 River-Intake",Profile!$L$5:$L$2360,"yes")=0,"no points between tanks",_xlfn.MINIFS(Profile!$H$5:$H$2360,Profile!$A$5:$A$2360,"Z1 River-Intake",Profile!$L$5:$L$2360,"yes")) -> no points between tanks | C30: m | D30: if below the minimum, add that point to section D
A32: F. Step by step in words (updates with the numbers)
A33: ="1. Flow: "&TEXT(I12,"#,##0")&" m³/d in "&TEXT($B$7,"0")&" h → Q = "&TEXT(K12,"0.0")&" l/s, V = "&TEXT(M12,"0.00")&" m/s in "&A12&"." -> 1. Flow: 21,505 m³/d in 22 h → Q = 271.5 l/s, V = 0.96 m/s in ABSTRACTION.
A34: ="2. Friction (Hazen-Williams): "&A12&" loses hL = "&TEXT(P12,"0.00")&" m over "&TEXT(G12,"#,##0")&" m ("&TEXT(Q12,"0.00")&" m/km)." -> 2. Friction (Hazen-Williams): ABSTRACTION loses hL = 0.18 m over 100 m (1.78 m/km).
A35: ="3. Point 1 = MOMBA_RIVER water surface at its MINIMUM level z1 = "&TEXT($B$5,"0.00")&" m (p = 0, V ≈ 0)." -> 3. Point 1 = MOMBA_RIVER water surface at its MINIMUM level z1 = 1361.00 m (p = 0, V ≈ 0).
A36: ="4. Point 2: the hardest place to reach is "&$B$26&"; it needs the HGL at the zone start to be H_req = "&TEXT($B$25,"0.00")&" m (its level + residual + losses on the way)." -> 4. Point 2: the hardest place to reach is MOMBA_INTAKE; it needs the HGL at the zone start to be H_req = 1360.18 m (its level + residual + losses on the way).
A37: ="5. Bernoulli without pump: z1 = H_req + surplus → surplus = "&TEXT($B$5,"0.00")&" − "&TEXT($B$25,"0.00")&" = "&TEXT($B$27,"0.00")&" m." -> 5. Bernoulli without pump: z1 = H_req + surplus → surplus = 1361.00 − 1360.18 = 0.82 m.
A38: ="6. With the supplying tank full (MAXIMUM level "&TEXT($B$6,"0.00")&" m) the surplus is "&TEXT($B$28,"0.00")&" m. "&IF($B$27<-0.005,"Negative at minimum level: the zone cannot deliver – change pipe or levels.","A flow control valve burns this so the flow stays at design.") -> 6. With the supplying tank full (MAXIMUM level 1364.50 m) the surplus is 4.32 m. A flow control valve burns this so the flow stays at design.
A39: ="8. Pressure: lowest pressure along the route = "&TEXT($B$30,"0.0")&" m (minimum allowed "&TEXT(p_min,"0")&" m); pipe class from section D and sheet Profile." -> 8. Pressure: lowest pressure along the route = no points between tanks m (minimum allowed 2 m); pipe class from section D and sheet Profile.

Sheet Z2 Intake-Grit
A1: Zone 2 – Intake low-lift pumps to grit tank (pumped)
A2: Low-lift pumps lift raw water from the intake sump into the grit tank. Pump head = level the water must reach in the grit tank + losses − sump level.
A4: A. Inputs (levels come from sheet 'Levels')
A5: Start: MOMBA_INTAKE MINIMUM water level | B5: =Levels!$F$6 -> 1360 | C5: m a.s.l. | D5: point 1 of Bernoulli, design case (least energy at the start)
A6: Start: MOMBA_INTAKE MAXIMUM water level | B6: =Levels!$G$6 -> 1364 | C6: m a.s.l. | D6: low-head case for pumps / highest energy for gravity
A7: Operating hours per day | B7: 22 | C7: h/d | D7: ER: pumps 22 h/d; gravity 24 h/d
A8: Static level for pressure class | B8: =MAX(Levels!$L$7) -> 1368 | C8: m a.s.l. | D8: highest arrival level at the end of the zone (pipe full, pumps stopped)
A9: Number of duty pumps | B9: 1 | C9: no. | D9: working pumps sharing the flow
A10: Number of standby pumps | B10: 1 | C10: no. | D10: for information
A11: Pump efficiency η_p | B11: 0.75 | C11: – | D11: ASSUMED – use the pump curve
A12: Motor efficiency η_m | B12: 0.94 | C12: – | D12: ASSUMED
A13: ER duty flow per pump | B13: 978 | C13: m³/h | D13: Employer's Requirements
A14: ER duty head | B14: 10 | C14: m | D14: Employer's Requirements
A16: B. Pipes – flow (continuity) and friction (Hazen-Williams)
A17: Pipe | B17: From | C17: To | D17: Upstream pipe | E17: DN | F17: Internal D (mm) | G17: Length L (m) | H17: C (H-W) | I17: Daily volume (m³/d) | J17: Q (m³/s) | K17: Q (l/s) | L17: Area (m²) | M17: V (m/s) | N17: hf friction (m) | O17: hm minor (m) | P17: hL total (m) | Q17: Gradient (m/km) | R17: Loss before this pipe (m) | S17: HGL start (m) | T17: HGL end (m) | U17: Surge Δh = aV/g (m)
A18: LL_DELIVERY | B18: MOMBA_INTAKE | C18: GRIT_TANK | D18: – | E18: 600 | F18: =E18 -> 600 | G18: 30 | H18: =C_default -> 120 | I18: =Demands!$B$27 -> 21505.376 | J18: =I18/($B$7*3600) -> 0.27153253 | K18: =J18*1000 -> 271.53253 | L18: =PI()*(F18/1000)^2/4 -> 0.28274334 | M18: =J18/L18 -> 0.96034987 | N18: =10.67*G18*J18^1.852/(H18^1.852*(F18/1000)^4.8704) -> 0.048592837 | O18: =k_minor*N18 -> 0.0048592837 | P18: =N18+O18 -> 0.05345212 | Q18: =P18/G18*1000 -> 1.7817373 | R18: 0 | S18: =$B$31-R18 -> 1369.0535 | T18: =S18-P18 -> 1369 | U18: =wave*M18/g -> 97.894992
A20: C. Destinations – Bernoulli to each receiving water surface (levels from 'Levels')
A21: Destination | B21: Ends with pipe | C21: MIN level (m) | D21: MAX level (m) | E21: Arrival level (m) | F21: Residual (m) | G21: z2 = arrival + residual (m) | H21: Head needed at zone start = z2 + losses (m) | I21: Arriving HGL, design case (m) | J21: Excess head, design case (m) | K21: Excess head, start at MAX level (m) | L21: Comment
A22: GRIT_TANK | B22: LL_DELIVERY | C22: =Levels!$F$7 -> 1366.5 | D22: =Levels!$G$7 -> 1368 | E22: =Levels!$L$7 -> 1368 | F22: =h_res -> 1 | G22: =E22+F22 -> 1369 | H22: =G22+R18+P18 -> 1369.0535 | I22: =T18 -> 1369 | J22: =I22-G22 -> 0 | K22: =J22+($B$6-$B$5) -> 4 | L22: =IF(J22<-0.005,"NOT REACHED – more head needed",IF(K22>fcv_limit,"fit flow control valve / PRV (burns "&TEXT(J22,"0.0")&"–"&TEXT(K22,"0.0")&" m)","OK")) -> OK
A24: D. Critical points along the pipes – pressure check (add your own rows)
A25: Pipe | B25: Chainage in pipe x (m) | C25: Ground level (m) | D25: Pipe crown (m) | E25: Head needed at zone start (m) | F25: HGL at point (m) | G25: Pressure (m) | H25: Static (m) | I25: Working (m) | J25: Working (bar) | K25: PN required | L25: Transient min = p − Δh (m) | M25: Note | N25: Status
D26: =IF($A26="","",C26-cover) | E26: =IF($A26="","",D26+p_min+INDEX($R$18:$R$18,MATCH($A26,$A$18:$A$18,0))+INDEX($P$18:$P$18,MATCH($A26,$A$18:$A$18,0))*B26/INDEX($G$18:$G$18,MATCH($A26,$A$18:$A$18,0))) | F26: =IF($A26="","",INDEX($S$18:$S$18,MATCH($A26,$A$18:$A$18,0))-INDEX($P$18:$P$18,MATCH($A26,$A$18:$A$18,0))*B26/INDEX($G$18:$G$18,MATCH($A26,$A$18:$A$18,0))) | G26: =IF($A26="","",F26-D26) | H26: =IF($A26="","",$B$8-D26) | I26: =IF($A26="","",MAX(G26,H26)) | J26: =IF($A26="","",I26*bar_per_m) | K26: =IF($A26="","",IFERROR("PN"&SMALL(PN_list,COUNTIF(PN_list,"<"&J26)+1),"> max PN")) | L26: =IF($A26="","",G26-INDEX($U$18:$U$18,MATCH($A26,$A$18:$A$18,0))) | M26: add a point: pipe ID, chainage, ground level | N26: =IF($A26="","",IF(G26<0,"NEGATIVE PRESSURE",IF(G26<p_min-0.005,"below minimum","OK")))
D27: =IF($A27="","",C27-cover) | E27: =IF($A27="","",D27+p_min+INDEX($R$18:$R$18,MATCH($A27,$A$18:$A$18,0))+INDEX($P$18:$P$18,MATCH($A27,$A$18:$A$18,0))*B27/INDEX($G$18:$G$18,MATCH($A27,$A$18:$A$18,0))) | F27: =IF($A27="","",INDEX($S$18:$S$18,MATCH($A27,$A$18:$A$18,0))-INDEX($P$18:$P$18,MATCH($A27,$A$18:$A$18,0))*B27/INDEX($G$18:$G$18,MATCH($A27,$A$18:$A$18,0))) | G27: =IF($A27="","",F27-D27) | H27: =IF($A27="","",$B$8-D27) | I27: =IF($A27="","",MAX(G27,H27)) | J27: =IF($A27="","",I27*bar_per_m) | K27: =IF($A27="","",IFERROR("PN"&SMALL(PN_list,COUNTIF(PN_list,"<"&J27)+1),"> max PN")) | L27: =IF($A27="","",G27-INDEX($U$18:$U$18,MATCH($A27,$A$18:$A$18,0))) | M27: add a point: pipe ID, chainage, ground level | N27: =IF($A27="","",IF(G27<0,"NEGATIVE PRESSURE",IF(G27<p_min-0.005,"below minimum","OK")))
D28: =IF($A28="","",C28-cover) | E28: =IF($A28="","",D28+p_min+INDEX($R$18:$R$18,MATCH($A28,$A$18:$A$18,0))+INDEX($P$18:$P$18,MATCH($A28,$A$18:$A$18,0))*B28/INDEX($G$18:$G$18,MATCH($A28,$A$18:$A$18,0))) | F28: =IF($A28="","",INDEX($S$18:$S$18,MATCH($A28,$A$18:$A$18,0))-INDEX($P$18:$P$18,MATCH($A28,$A$18:$A$18,0))*B28/INDEX($G$18:$G$18,MATCH($A28,$A$18:$A$18,0))) | G28: =IF($A28="","",F28-D28) | H28: =IF($A28="","",$B$8-D28) | I28: =IF($A28="","",MAX(G28,H28)) | J28: =IF($A28="","",I28*bar_per_m) | K28: =IF($A28="","",IFERROR("PN"&SMALL(PN_list,COUNTIF(PN_list,"<"&J28)+1),"> max PN")) | L28: =IF($A28="","",G28-INDEX($U$18:$U$18,MATCH($A28,$A$18:$A$18,0))) | M28: add a point: pipe ID, chainage, ground level | N28: =IF($A28="","",IF(G28<0,"NEGATIVE PRESSURE",IF(G28<p_min-0.005,"below minimum","OK")))
A30: E. Bernoulli result
A31: Head needed at zone start H_req | B31: =MAX($H$22:$H$22,$E$26:$E$28) -> 1369.0535 | C31: m a.s.l. | D31: largest of sections C, C2 (junctions) and D (points)
A32: Set by | B32: =IF(MAX($E$26:$E$28)>=MAX($H$22:$H$22),"point on "&INDEX($A$26:$A$28,MATCH(MAX($E$26:$E$28),$E$26:$E$28,0)),INDEX($A$22:$A$22,MATCH(MAX($H$22:$H$22),$H$22:$H$22,0))) -> GRIT_TANK | D32: governing destination, junction or point
A33: Hp = H_req − z1 (suction at MINIMUM level) | B33: =$B$31-$B$5 -> 9.0534521 | C33: m | D33: z1 + 0 + 0 + Hp = H_req (p = 0, V ≈ 0 at the sump surface)
A34: TDH design (suction at MINIMUM level) | B34: =$B$33+h_station -> 12.053452 | C34: m | D34: Hp + station losses → size pump and motor with this
A35: TDH low-head (suction at MAXIMUM level) | B35: =$B$31-$B$6+h_station -> 8.0534521 | C35: m | D35: pump must also operate here (more flow unless throttled / VFD)
A36: Total pumped flow | B36: =J18 -> 0.27153253 | C36: m³/s | D36: flow in the first pipe
A37: Flow per pump | B37: =$B$36/$B$9 -> 0.27153253 | C37: m³/s
A38: Flow per pump | B38: =$B$37*3600 -> 977.51711 | C38: m³/h | D38: compare ER duty flow
A39: Hydraulic power per pump P_h = ρgQH | B39: =1000*g*$B$37*$B$34/1000 -> 32.107192 | C39: kW
A40: Shaft power per pump P_s = P_h / η_p | B40: =$B$39/$B$11 -> 42.809589 | C40: kW
A41: Motor needed = P_s × margin | B41: =$B$40*motor_margin -> 49.231027 | C41: kW
A42: Standard motor per pump | B42: =IFERROR(SMALL(Motor_list,COUNTIF(Motor_list,"<"&$B$41)+1),"> list") -> 55 | C42: kW | D42: next size up
A43: Electricity per day | B43: =$B$9*$B$40*$B$7/$B$12 -> 1001.9265 | C43: kWh/d
A44: Specific energy | B44: =$B$43/I18 -> 0.046589584 | C44: kWh/m³
A45: Electricity cost per year | B45: =$B$43*365*tariff -> 0 | C45: per year | D45: uses Global tariff
...

Sheet Z3 Grit-WTP
A1: Zone 3 – Grit tank high-lift pumps to the WTP (pumped)
A2: High-lift pumps push raw water from the grit tank through the raw-water main into the WTP inlet (cascade aerator).
A4: A. Inputs (levels come from sheet 'Levels')
A5: Start: GRIT_TANK MINIMUM water level | B5: =Levels!$F$7 -> 1366.5 | C5: m a.s.l. | D5: point 1 of Bernoulli, design case (least energy at the start)
A6: Start: GRIT_TANK MAXIMUM water level | B6: =Levels!$G$7 -> 1368 | C6: m a.s.l. | D6: low-head case for pumps / highest energy for gravity
A7: Operating hours per day | B7: 22 | C7: h/d | D7: ER: pumps 22 h/d; gravity 24 h/d
A8: Static level for pressure class | B8: =MAX(Levels!$L$8) -> 1378 | C8: m a.s.l. | D8: highest arrival level at the end of the zone (pipe full, pumps stopped)
A9: Number of duty pumps | B9: 1 | C9: no. | D9: working pumps sharing the flow
A10: Number of standby pumps | B10: 1 | C10: no. | D10: for information
A11: Pump efficiency η_p | B11: 0.75 | C11: – | D11: ASSUMED – use the pump curve
A12: Motor efficiency η_m | B12: 0.94 | C12: – | D12: ASSUMED
A13: ER duty flow per pump | B13: 978 | C13: m³/h | D13: Employer's Requirements
A14: ER duty head | B14: 25 | C14: m | D14: Employer's Requirements
A16: B. Pipes – flow (continuity) and friction (Hazen-Williams)
A17: Pipe | B17: From | C17: To | D17: Upstream pipe | E17: DN | F17: Internal D (mm) | G17: Length L (m) | H17: C (H-W) | I17: Daily volume (m³/d) | J17: Q (m³/s) | K17: Q (l/s) | L17: Area (m²) | M17: V (m/s) | N17: hf friction (m) | O17: hm minor (m) | P17: hL total (m) | Q17: Gradient (m/km) | R17: Loss before this pipe (m) | S17: HGL start (m) | T17: HGL end (m) | U17: Surge Δh = aV/g (m)
A18: RAW_MAIN | B18: GRIT_TANK | C18: MOMBA_WTP | D18: – | E18: 600 | F18: =E18 -> 600 | G18: 1078.5 | H18: =C_default -> 120 | I18: =Demands!$B$26 -> 21505.376 | J18: =I18/($B$7*3600) -> 0.27153253 | K18: =J18*1000 -> 271.53253 | L18: =PI()*(F18/1000)^2/4 -> 0.28274334 | M18: =J18/L18 -> 0.96034987 | N18: =10.67*G18*J18^1.852/(H18^1.852*(F18/1000)^4.8704) -> 1.7469125 | O18: =k_minor*N18 -> 0.17469125 | P18: =N18+O18 -> 1.9216037 | Q18: =P18/G18*1000 -> 1.7817373 | R18: 0 | S18: =$B$33-R18 -> 1380.9216 | T18: =S18-P18 -> 1379 | U18: =wave*M18/g -> 97.894992
A20: C. Destinations – Bernoulli to each receiving water surface (levels from 'Levels')
A21: Destination | B21: Ends with pipe | C21: MIN level (m) | D21: MAX level (m) | E21: Arrival level (m) | F21: Residual (m) | G21: z2 = arrival + residual (m) | H21: Head needed at zone start = z2 + losses (m) | I21: Arriving HGL, design case (m) | J21: Excess head, design case (m) | K21: Excess head, start at MAX level (m) | L21: Comment
A22: MOMBA_WTP | B22: RAW_MAIN | C22: =Levels!$F$8 -> 1368.5 | D22: =Levels!$G$8 -> 1373 | E22: =Levels!$L$8 -> 1378 | F22: =h_res -> 1 | G22: =E22+F22 -> 1379 | H22: =G22+R18+P18 -> 1380.9216 | I22: =T18 -> 1379 | J22: =I22-G22 -> 0 | K22: =J22+($B$6-$B$5) -> 1.5 | L22: =IF(J22<-0.005,"NOT REACHED – more head needed",IF(K22>fcv_limit,"fit flow control valve / PRV (burns "&TEXT(J22,"0.0")&"–"&TEXT(K22,"0.0")&" m)","OK")) -> OK
A24: D. Critical points along the pipes – pressure check (add your own rows)
A25: Pipe | B25: Chainage in pipe x (m) | C25: Ground level (m) | D25: Pipe crown (m) | E25: Head needed at zone start (m) | F25: HGL at point (m) | G25: Pressure (m) | H25: Static (m) | I25: Working (m) | J25: Working (bar) | K25: PN required | L25: Transient min = p − Δh (m) | M25: Note | N25: Status
A26: RAW_MAIN | B26: 778.5 | C26: 1372.43 | D26: =IF($A26="","",C26-cover) -> 1371.23 | E26: =IF($A26="","",D26+p_min+INDEX($R$18:$R$18,MATCH($A26,$A$18:$A$18,0))+INDEX($P$18:$P$18,MATCH($A26,$A$18:$A$18,0))*B26/INDEX($G$18:$G$18,MATCH($A26,$A$18:$A$18,0))) -> 1374.6171 | F26: =IF($A26="","",INDEX($S$18:$S$18,MATCH($A26,$A$18:$A$18,0))-INDEX($P$18:$P$18,MATCH($A26,$A$18:$A$18,0))*B26/INDEX($G$18:$G$18,MATCH($A26,$A$18:$A$18,0))) -> 1379.5345 | G26: =IF($A26="","",F26-D26) -> 8.3045212 | H26: =IF($A26="","",$B$8-D26) -> 6.77 | I26: =IF($A26="","",MAX(G26,H26)) -> 8.3045212 | J26: =IF($A26="","",I26*bar_per_m) -> 0.81467353 | K26: =IF($A26="","",IFERROR("PN"&SMALL(PN_list,COUNTIF(PN_list,"<"&J26)+1),"> max PN")) -> PN10 | L26: =IF($A26="","",G26-INDEX($U$18:$U$18,MATCH($A26,$A$18:$A$18,0))) -> -89.590471 | M26: critical high point | N26: =IF($A26="","",IF(G26<0,"NEGATIVE PRESSURE",IF(G26<p_min-0.005,"below minimum","OK"))) -> OK
A27: RAW_MAIN | B27: 129.8 | C27: 1365.87 | D27: =IF($A27="","",C27-cover) -> 1364.67 | E27: =IF($A27="","",D27+p_min+INDEX($R$18:$R$18,MATCH($A27,$A$18:$A$18,0))+INDEX($P$18:$P$18,MATCH($A27,$A$18:$A$18,0))*B27/INDEX($G$18:$G$18,MATCH($A27,$A$18:$A$18,0))) -> 1366.9013 | F27: =IF($A27="","",INDEX($S$18:$S$18,MATCH($A27,$A$18:$A$18,0))-INDEX($P$18:$P$18,MATCH($A27,$A$18:$A$18,0))*B27/INDEX($G$18:$G$18,MATCH($A27,$A$18:$A$18,0))) -> 1380.6903 | G27: =IF($A27="","",F27-D27) -> 16.020334 | H27: =IF($A27="","",$B$8-D27) -> 13.33 | I27: =IF($A27="","",MAX(G27,H27)) -> 16.020334 | J27: =IF($A27="","",I27*bar_per_m) -> 1.5715948 | K27: =IF($A27="","",IFERROR("PN"&SMALL(PN_list,COUNTIF(PN_list,"<"&J27)+1),"> max PN")) -> PN10 | L27: =IF($A27="","",G27-INDEX($U$18:$U$18,MATCH($A27,$A$18:$A$18,0))) -> -81.874658 | M27: lowest point (highest static pressure) | N27: =IF($A27="","",IF(G27<0,"NEGATIVE PRESSURE",IF(G27<p_min-0.005,"below minimum","OK"))) -> OK
D28: =IF($A28="","",C28-cover) | E28: =IF($A28="","",D28+p_min+INDEX($R$18:$R$18,MATCH($A28,$A$18:$A$18,0))+INDEX($P$18:$P$18,MATCH($A28,$A$18:$A$18,0))*B28/INDEX($G$18:$G$18,MATCH($A28,$A$18:$A$18,0))) | F28: =IF($A28="","",INDEX($S$18:$S$18,MATCH($A28,$A$18:$A$18,0))-INDEX($P$18:$P$18,MATCH($A28,$A$18:$A$18,0))*B28/INDEX($G$18:$G$18,MATCH($A28,$A$18:$A$18,0))) | G28: =IF($A28="","",F28-D28) | H28: =IF($A28="","",$B$8-D28) | I28: =IF($A28="","",MAX(G28,H28)) | J28: =IF($A28="","",I28*bar_per_m) | K28: =IF($A28="","",IFERROR("PN"&SMALL(PN_list,COUNTIF(PN_list,"<"&J28)+1),"> max PN")) | L28: =IF($A28="","",G28-INDEX($U$18:$U$18,MATCH($A28,$A$18:$A$18,0))) | M28: add a point: pipe ID, chainage, ground level | N28: =IF($A28="","",IF(G28<0,"NEGATIVE PRESSURE",IF(G28<p_min-0.005,"below minimum","OK")))
D29: =IF($A29="","",C29-cover) | E29: =IF($A29="","",D29+p_min+INDEX($R$18:$R$18,MATCH($A29,$A$18:$A$18,0))+INDEX($P$18:$P$18,MATCH($A29,$A$18:$A$18,0))*B29/INDEX($G$18:$G$18,MATCH($A29,$A$18:$A$18,0))) | F29: =IF($A29="","",INDEX($S$18:$S$18,MATCH($A29,$A$18:$A$18,0))-INDEX($P$18:$P$18,MATCH($A29,$A$18:$A$18,0))*B29/INDEX($G$18:$G$18,MATCH($A29,$A$18:$A$18,0))) | G29: =IF($A29="","",F29-D29) | H29: =IF($A29="","",$B$8-D29) | I29: =IF($A29="","",MAX(G29,H29)) | J29: =IF($A29="","",I29*bar_per_m) | K29: =IF($A29="","",IFERROR("PN"&SMALL(PN_list,COUNTIF(PN_list,"<"&J29)+1),"> max PN")) | L29: =IF($A29="","",G29-INDEX($U$18:$U$18,MATCH($A29,$A$18:$A$18,0))) | M29: add a point: pipe ID, chainage, ground level | N29: =IF($A29="","",IF(G29<0,"NEGATIVE PRESSURE",IF(G29<p_min-0.005,"below minimum","OK")))
D30: =IF($A30="","",C30-cover) | E30: =IF($A30="","",D30+p_min+INDEX($R$18:$R$18,MATCH($A30,$A$18:$A$18,0))+INDEX($P$18:$P$18,MATCH($A30,$A$18:$A$18,0))*B30/INDEX($G$18:$G$18,MATCH($A30,$A$18:$A$18,0))) | F30: =IF($A30="","",INDEX($S$18:$S$18,MATCH($A30,$A$18:$A$18,0))-INDEX($P$18:$P$18,MATCH($A30,$A$18:$A$18,0))*B30/INDEX($G$18:$G$18,MATCH($A30,$A$18:$A$18,0))) | G30: =IF($A30="","",F30-D30) | H30: =IF($A30="","",$B$8-D30) | I30: =IF($A30="","",MAX(G30,H30)) | J30: =IF($A30="","",I30*bar_per_m) | K30: =IF($A30="","",IFERROR("PN"&SMALL(PN_list,COUNTIF(PN_list,"<"&J30)+1),"> max PN")) | L30: =IF($A30="","",G30-INDEX($U$18:$U$18,MATCH($A30,$A$18:$A$18,0))) | M30: add a point: pipe ID, chainage, ground level | N30: =IF($A30="","",IF(G30<0,"NEGATIVE PRESSURE",IF(G30<p_min-0.005,"below minimum","OK")))
A32: E. Bernoulli result
A33: Head needed at zone start H_req | B33: =MAX($H$22:$H$22,$E$26:$E$30) -> 1380.9216 | C33: m a.s.l. | D33: largest of sections C, C2 (junctions) and D (points)
A34: Set by | B34: =IF(MAX($E$26:$E$30)>=MAX($H$22:$H$22),"point on "&INDEX($A$26:$A$30,MATCH(MAX($E$26:$E$30),$E$26:$E$30,0)),INDEX($A$22:$A$22,MATCH(MAX($H$22:$H$22),$H$22:$H$22,0))) -> MOMBA_WTP | D34: governing destination, junction or point
A35: Hp = H_req − z1 (suction at MINIMUM level) | B35: =$B$33-$B$5 -> 14.421604 | C35: m | D35: z1 + 0 + 0 + Hp = H_req (p = 0, V ≈ 0 at the sump surface)
A36: TDH design (suction at MINIMUM level) | B36: =$B$35+h_station -> 17.421604 | C36: m | D36: Hp + station losses → size pump and motor with this
A37: TDH low-head (suction at MAXIMUM level) | B37: =$B$33-$B$6+h_station -> 15.921604 | C37: m | D37: pump must also operate here (more flow unless throttled / VFD)
A38: Total pumped flow | B38: =J18 -> 0.27153253 | C38: m³/s | D38: flow in the first pipe
A39: Flow per pump | B39: =$B$38/$B$9 -> 0.27153253 | C39: m³/s
A40: Flow per pump | B40: =$B$39*3600 -> 977.51711 | C40: m³/h | D40: compare ER duty flow
A41: Hydraulic power per pump P_h = ρgQH | B41: =1000*g*$B$39*$B$36/1000 -> 46.40652 | C41: kW
A42: Shaft power per pump P_s = P_h / η_p | B42: =$B$41/$B$11 -> 61.87536 | C42: kW
A43: Motor needed = P_s × margin | B43: =$B$42*motor_margin -> 71.156664 | C43: kW
A44: Standard motor per pump | B44: =IFERROR(SMALL(Motor_list,COUNTIF(Motor_list,"<"&$B$43)+1),"> list") -> 75 | C44: kW | D44: next size up
A45: Electricity per day | B45: =$B$9*$B$42*$B$7/$B$12 -> 1448.1467 | C45: kWh/d
...

Sheet Z4 WTP-Ikana
A1: Zone 4 – WTP clear-water pumps to Ikana GBR (pumped)
A2: The WTP pumps lift treated water about 300 m over ~20 km from the clear-water tank to Ikana GBR on the hill. Most of the head is lift; friction is the rest. Pressure is highest at the pumps.
A4: A. Inputs (levels come from sheet 'Levels')
A5: Start: MOMBA_WTP MINIMUM water level | B5: =Levels!$F$8 -> 1368.5 | C5: m a.s.l. | D5: point 1 of Bernoulli, design case (least energy at the start)
A6: Start: MOMBA_WTP MAXIMUM water level | B6: =Levels!$G$8 -> 1373 | C6: m a.s.l. | D6: low-head case for pumps / highest energy for gravity
A7: Operating hours per day | B7: 22 | C7: h/d | D7: ER: pumps 22 h/d; gravity 24 h/d
A8: Static level for pressure class | B8: =MAX(Levels!$L$9) -> 1668 | C8: m a.s.l. | D8: highest arrival level at the end of the zone (pipe full, pumps stopped)
A9: Number of duty pumps | B9: 3 | C9: no. | D9: working pumps sharing the flow
A10: Number of standby pumps | B10: 1 | C10: no. | D10: for information
A11: Pump efficiency η_p | B11: 0.78 | C11: – | D11: ASSUMED – use the pump curve
A12: Motor efficiency η_m | B12: 0.95 | C12: – | D12: ASSUMED
A13: ER duty flow per pump | B13: 304 | C13: m³/h | D13: Employer's Requirements
A14: ER duty head | B14: 330 | C14: m | D14: Employer's Requirements
A16: B. Pipes – flow (continuity) and friction (Hazen-Williams)
A17: Pipe | B17: From | C17: To | D17: Upstream pipe | E17: DN | F17: Internal D (mm) | G17: Length L (m) | H17: C (H-W) | I17: Daily volume (m³/d) | J17: Q (m³/s) | K17: Q (l/s) | L17: Area (m²) | M17: V (m/s) | N17: hf friction (m) | O17: hm minor (m) | P17: hL total (m) | Q17: Gradient (m/km) | R17: Loss before this pipe (m) | S17: HGL start (m) | T17: HGL end (m) | U17: Surge Δh = aV/g (m)
A18: WTP_IKANA_RM | B18: MOMBA_WTP | C18: IKANA_GBR | D18: – | E18: 600 | F18: =E18 -> 600 | G18: 19665.6 | H18: =C_default -> 120 | I18: =Demands!$B$25 -> 20000 | J18: =I18/($B$7*3600) -> 0.25252525 | K18: =J18*1000 -> 252.52525 | L18: =PI()*(F18/1000)^2/4 -> 0.28274334 | M18: =J18/L18 -> 0.89312538 | N18: =10.67*G18*J18^1.852/(H18^1.852*(F18/1000)^4.8704) -> 27.847654 | O18: =k_minor*N18 -> 2.7847654 | P18: =N18+O18 -> 30.63242 | Q18: =P18/G18*1000 -> 1.5576651 | R18: 0 | S18: =$B$33-R18 -> 1699.6324 | T18: =S18-P18 -> 1669 | U18: =wave*M18/g -> 91.042343
A20: C. Destinations – Bernoulli to each receiving water surface (levels from 'Levels')
A21: Destination | B21: Ends with pipe | C21: MIN level (m) | D21: MAX level (m) | E21: Arrival level (m) | F21: Residual (m) | G21: z2 = arrival + residual (m) | H21: Head needed at zone start = z2 + losses (m) | I21: Arriving HGL, design case (m) | J21: Excess head, design case (m) | K21: Excess head, start at MAX level (m) | L21: Comment
A22: IKANA_GBR | B22: WTP_IKANA_RM | C22: =Levels!$F$9 -> 1663.3 | D22: =Levels!$G$9 -> 1668 | E22: =Levels!$L$9 -> 1668 | F22: =h_res -> 1 | G22: =E22+F22 -> 1669 | H22: =G22+R18+P18 -> 1699.6324 | I22: =T18 -> 1669 | J22: =I22-G22 -> 0 | K22: =J22+($B$6-$B$5) -> 4.5 | L22: =IF(J22<-0.005,"NOT REACHED – more head needed",IF(K22>fcv_limit,"fit flow control valve / PRV (burns "&TEXT(J22,"0.0")&"–"&TEXT(K22,"0.0")&" m)","OK")) -> OK
A24: D. Critical points along the pipes – pressure check (add your own rows)
A25: Pipe | B25: Chainage in pipe x (m) | C25: Ground level (m) | D25: Pipe crown (m) | E25: Head needed at zone start (m) | F25: HGL at point (m) | G25: Pressure (m) | H25: Static (m) | I25: Working (m) | J25: Working (bar) | K25: PN required | L25: Transient min = p − Δh (m) | M25: Note | N25: Status
A26: WTP_IKANA_RM | B26: 19645.6 | C26: 1661.36 | D26: =IF($A26="","",C26-cover) -> 1660.16 | E26: =IF($A26="","",D26+p_min+INDEX($R$18:$R$18,MATCH($A26,$A$18:$A$18,0))+INDEX($P$18:$P$18,MATCH($A26,$A$18:$A$18,0))*B26/INDEX($G$18:$G$18,MATCH($A26,$A$18:$A$18,0))) -> 1692.7613 | F26: =IF($A26="","",INDEX($S$18:$S$18,MATCH($A26,$A$18:$A$18,0))-INDEX($P$18:$P$18,MATCH($A26,$A$18:$A$18,0))*B26/INDEX($G$18:$G$18,MATCH($A26,$A$18:$A$18,0))) -> 1669.0312 | G26: =IF($A26="","",F26-D26) -> 8.8711533 | H26: =IF($A26="","",$B$8-D26) -> 7.84 | I26: =IF($A26="","",MAX(G26,H26)) -> 8.8711533 | J26: =IF($A26="","",I26*bar_per_m) -> 0.87026014 | K26: =IF($A26="","",IFERROR("PN"&SMALL(PN_list,COUNTIF(PN_list,"<"&J26)+1),"> max PN")) -> PN10 | L26: =IF($A26="","",G26-INDEX($U$18:$U$18,MATCH($A26,$A$18:$A$18,0))) -> -82.171189 | M26: critical high point | N26: =IF($A26="","",IF(G26<0,"NEGATIVE PRESSURE",IF(G26<p_min-0.005,"below minimum","OK"))) -> OK
A27: WTP_IKANA_RM | B27: 50 | C27: 1373.21 | D27: =IF($A27="","",C27-cover) -> 1372.01 | E27: =IF($A27="","",D27+p_min+INDEX($R$18:$R$18,MATCH($A27,$A$18:$A$18,0))+INDEX($P$18:$P$18,MATCH($A27,$A$18:$A$18,0))*B27/INDEX($G$18:$G$18,MATCH($A27,$A$18:$A$18,0))) -> 1374.0879 | F27: =IF($A27="","",INDEX($S$18:$S$18,MATCH($A27,$A$18:$A$18,0))-INDEX($P$18:$P$18,MATCH($A27,$A$18:$A$18,0))*B27/INDEX($G$18:$G$18,MATCH($A27,$A$18:$A$18,0))) -> 1699.5545 | G27: =IF($A27="","",F27-D27) -> 327.54454 | H27: =IF($A27="","",$B$8-D27) -> 295.99 | I27: =IF($A27="","",MAX(G27,H27)) -> 327.54454 | J27: =IF($A27="","",I27*bar_per_m) -> 32.132119 | K27: =IF($A27="","",IFERROR("PN"&SMALL(PN_list,COUNTIF(PN_list,"<"&J27)+1),"> max PN")) -> PN40 | L27: =IF($A27="","",G27-INDEX($U$18:$U$18,MATCH($A27,$A$18:$A$18,0))) -> 236.50219 | M27: lowest point (highest static pressure) | N27: =IF($A27="","",IF(G27<0,"NEGATIVE PRESSURE",IF(G27<p_min-0.005,"below minimum","OK"))) -> OK
D28: =IF($A28="","",C28-cover) | E28: =IF($A28="","",D28+p_min+INDEX($R$18:$R$18,MATCH($A28,$A$18:$A$18,0))+INDEX($P$18:$P$18,MATCH($A28,$A$18:$A$18,0))*B28/INDEX($G$18:$G$18,MATCH($A28,$A$18:$A$18,0))) | F28: =IF($A28="","",INDEX($S$18:$S$18,MATCH($A28,$A$18:$A$18,0))-INDEX($P$18:$P$18,MATCH($A28,$A$18:$A$18,0))*B28/INDEX($G$18:$G$18,MATCH($A28,$A$18:$A$18,0))) | G28: =IF($A28="","",F28-D28) | H28: =IF($A28="","",$B$8-D28) | I28: =IF($A28="","",MAX(G28,H28)) | J28: =IF($A28="","",I28*bar_per_m) | K28: =IF($A28="","",IFERROR("PN"&SMALL(PN_list,COUNTIF(PN_list,"<"&J28)+1),"> max PN")) | L28: =IF($A28="","",G28-INDEX($U$18:$U$18,MATCH($A28,$A$18:$A$18,0))) | M28: add a point: pipe ID, chainage, ground level | N28: =IF($A28="","",IF(G28<0,"NEGATIVE PRESSURE",IF(G28<p_min-0.005,"below minimum","OK")))
D29: =IF($A29="","",C29-cover) | E29: =IF($A29="","",D29+p_min+INDEX($R$18:$R$18,MATCH($A29,$A$18:$A$18,0))+INDEX($P$18:$P$18,MATCH($A29,$A$18:$A$18,0))*B29/INDEX($G$18:$G$18,MATCH($A29,$A$18:$A$18,0))) | F29: =IF($A29="","",INDEX($S$18:$S$18,MATCH($A29,$A$18:$A$18,0))-INDEX($P$18:$P$18,MATCH($A29,$A$18:$A$18,0))*B29/INDEX($G$18:$G$18,MATCH($A29,$A$18:$A$18,0))) | G29: =IF($A29="","",F29-D29) | H29: =IF($A29="","",$B$8-D29) | I29: =IF($A29="","",MAX(G29,H29)) | J29: =IF($A29="","",I29*bar_per_m) | K29: =IF($A29="","",IFERROR("PN"&SMALL(PN_list,COUNTIF(PN_list,"<"&J29)+1),"> max PN")) | L29: =IF($A29="","",G29-INDEX($U$18:$U$18,MATCH($A29,$A$18:$A$18,0))) | M29: add a point: pipe ID, chainage, ground level | N29: =IF($A29="","",IF(G29<0,"NEGATIVE PRESSURE",IF(G29<p_min-0.005,"below minimum","OK")))
D30: =IF($A30="","",C30-cover) | E30: =IF($A30="","",D30+p_min+INDEX($R$18:$R$18,MATCH($A30,$A$18:$A$18,0))+INDEX($P$18:$P$18,MATCH($A30,$A$18:$A$18,0))*B30/INDEX($G$18:$G$18,MATCH($A30,$A$18:$A$18,0))) | F30: =IF($A30="","",INDEX($S$18:$S$18,MATCH($A30,$A$18:$A$18,0))-INDEX($P$18:$P$18,MATCH($A30,$A$18:$A$18,0))*B30/INDEX($G$18:$G$18,MATCH($A30,$A$18:$A$18,0))) | G30: =IF($A30="","",F30-D30) | H30: =IF($A30="","",$B$8-D30) | I30: =IF($A30="","",MAX(G30,H30)) | J30: =IF($A30="","",I30*bar_per_m) | K30: =IF($A30="","",IFERROR("PN"&SMALL(PN_list,COUNTIF(PN_list,"<"&J30)+1),"> max PN")) | L30: =IF($A30="","",G30-INDEX($U$18:$U$18,MATCH($A30,$A$18:$A$18,0))) | M30: add a point: pipe ID, chainage, ground level | N30: =IF($A30="","",IF(G30<0,"NEGATIVE PRESSURE",IF(G30<p_min-0.005,"below minimum","OK")))
A32: E. Bernoulli result
A33: Head needed at zone start H_req | B33: =MAX($H$22:$H$22,$E$26:$E$30) -> 1699.6324 | C33: m a.s.l. | D33: largest of sections C, C2 (junctions) and D (points)
A34: Set by | B34: =IF(MAX($E$26:$E$30)>=MAX($H$22:$H$22),"point on "&INDEX($A$26:$A$30,MATCH(MAX($E$26:$E$30),$E$26:$E$30,0)),INDEX($A$22:$A$22,MATCH(MAX($H$22:$H$22),$H$22:$H$22,0))) -> IKANA_GBR | D34: governing destination, junction or point
A35: Hp = H_req − z1 (suction at MINIMUM level) | B35: =$B$33-$B$5 -> 331.13242 | C35: m | D35: z1 + 0 + 0 + Hp = H_req (p = 0, V ≈ 0 at the sump surface)
A36: TDH design (suction at MINIMUM level) | B36: =$B$35+h_station -> 334.13242 | C36: m | D36: Hp + station losses → size pump and motor with this
A37: TDH low-head (suction at MAXIMUM level) | B37: =$B$33-$B$6+h_station -> 329.63242 | C37: m | D37: pump must also operate here (more flow unless throttled / VFD)
A38: Total pumped flow | B38: =J18 -> 0.25252525 | C38: m³/s | D38: flow in the first pipe
A39: Flow per pump | B39: =$B$38/$B$9 -> 0.084175084 | C39: m³/s
A40: Flow per pump | B40: =$B$39*3600 -> 303.0303 | C40: m³/h | D40: compare ER duty flow
A41: Hydraulic power per pump P_h = ρgQH | B41: =1000*g*$B$39*$B$36/1000 -> 275.91238 | C41: kW
A42: Shaft power per pump P_s = P_h / η_p | B42: =$B$41/$B$11 -> 353.73382 | C42: kW
